2018-12-15 11:46:21.364637: I tensorflow/core/platform/cpu_feature_guard.cc:137] Your CPU supports instructions that this TensorFlow binary was not compiled to use: SSE4.1 SSE4.2
2018-12-15 11:46:22.160162: I tensorflow/stream_executor/cuda/cuda_gpu_executor.cc:895] successful NUMA node read from SysFS had negative value (-1), but there must be at least one NUMA node, so returning NUMA node zero
2018-12-15 11:46:22.161901: I tensorflow/core/common_runtime/gpu/gpu_device.cc:1105] Found device 0 with properties: 
name: GeForce GTX 980 major: 5 minor: 2 memoryClockRate(GHz): 1.2155
pciBusID: 0000:0f:00.0
totalMemory: 3.95GiB freeMemory: 3.72GiB
2018-12-15 11:46:22.161935: I tensorflow/core/common_runtime/gpu/gpu_device.cc:1195] Creating TensorFlow device (/device:GPU:0) -> (device: 0, name: GeForce GTX 980, pci bus id: 0000:0f:00.0, compute capability: 5.2)
2018-12-15 11:46:22.880951: E tensorflow/stream_executor/cuda/cuda_blas.cc:444] failed to create cublas handle: CUBLAS_STATUS_NOT_INITIALIZED
2018-12-15 11:46:22.887310: E tensorflow/stream_executor/cuda/cuda_blas.cc:444] failed to create cublas handle: CUBLAS_STATUS_NOT_INITIALIZED
2018-12-15 11:46:22.895727: E tensorflow/stream_executor/cuda/cuda_blas.cc:444] failed to create cublas handle: CUBLAS_STATUS_NOT_INITIALIZED
2018-12-15 11:46:22.903611: E tensorflow/stream_executor/cuda/cuda_blas.cc:444] failed to create cublas handle: CUBLAS_STATUS_NOT_INITIALIZED
2018-12-15 11:46:22.912285: E tensorflow/stream_executor/cuda/cuda_blas.cc:444] failed to create cublas handle: CUBLAS_STATUS_NOT_INITIALIZED
2018-12-15 11:46:22.925533: E tensorflow/stream_executor/cuda/cuda_blas.cc:444] failed to create cublas handle: CUBLAS_STATUS_NOT_INITIALIZED
2018-12-15 11:46:22.937820: E tensorflow/stream_executor/cuda/cuda_blas.cc:444] failed to create cublas handle: CUBLAS_STATUS_NOT_INITIALIZED
2018-12-15 11:46:22.950995: E tensorflow/stream_executor/cuda/cuda_blas.cc:444] failed to create cublas handle: CUBLAS_STATUS_NOT_INITIALIZED
2018-12-15 11:46:22.962241: E tensorflow/stream_executor/cuda/cuda_blas.cc:444] failed to create cublas handle: CUBLAS_STATUS_NOT_INITIALIZED
2018-12-15 11:46:22.970887: E tensorflow/stream_executor/cuda/cuda_blas.cc:444] failed to create cublas handle: CUBLAS_STATUS_NOT_INITIALIZED
2018-12-15 11:46:22.983021: E tensorflow/stream_executor/cuda/cuda_blas.cc:444] failed to create cublas handle: CUBLAS_STATUS_NOT_INITIALIZED
2018-12-15 11:46:22.989756: E tensorflow/stream_executor/cuda/cuda_blas.cc:444] failed to create cublas handle: CUBLAS_STATUS_NOT_INITIALIZED
2018-12-15 11:46:22.997210: E tensorflow/stream_executor/cuda/cuda_blas.cc:444] failed to create cublas handle: CUBLAS_STATUS_NOT_INITIALIZED
2018-12-15 11:46:23.003055: E tensorflow/stream_executor/cuda/cuda_blas.cc:444] failed to create cublas handle: CUBLAS_STATUS_NOT_INITIALIZED
2018-12-15 11:46:23.012031: E tensorflow/stream_executor/cuda/cuda_blas.cc:444] failed to create cublas handle: CUBLAS_STATUS_NOT_INITIALIZED
2018-12-15 11:46:23.012061: W tensorflow/stream_executor/stream.cc:1901] attempting to perform BLAS operation using StreamExecutor without BLAS support
Using TensorFlow backend.
_________________________________________________________________
Layer (type)                 Output Shape              Param #   
=================================================================
dense_1 (Dense)              (None, 50)                2550      
_________________________________________________________________
activation_1 (Activation)    (None, 50)                0         
_________________________________________________________________
dense_2 (Dense)              (None, 50)                2550      
_________________________________________________________________
batch_normalization_1 (Batch (None, 50)                200       
_________________________________________________________________
activation_2 (Activation)    (None, 50)                0         
_________________________________________________________________
dense_3 (Dense)              (None, 50)                2550      
_________________________________________________________________
batch_normalization_2 (Batch (None, 50)                200       
_________________________________________________________________
activation_3 (Activation)    (None, 50)                0         
_________________________________________________________________
dense_4 (Dense)              (None, 50)                2550      
_________________________________________________________________
batch_normalization_3 (Batch (None, 50)                200       
_________________________________________________________________
activation_4 (Activation)    (None, 50)                0         
_________________________________________________________________
dense_5 (Dense)              (None, 2)                 102       
_________________________________________________________________
activation_5 (Activation)    (None, 2)                 0         
=================================================================
Total params: 10,902
Trainable params: 10,602
Non-trainable params: 300
_________________________________________________________________
Train on 10440 samples, validate on 3481 samples
Epoch 1/800
Traceback (most recent call last):
  File "/home/chikako_takasaki/.pyenv/versions/3.6.0/lib/python3.6/site-packages/tensorflow/python/client/session.py", line 1350, in _do_call
    return fn(*args)
  File "/home/chikako_takasaki/.pyenv/versions/3.6.0/lib/python3.6/site-packages/tensorflow/python/client/session.py", line 1329, in _run_fn
    status, run_metadata)
  File "/home/chikako_takasaki/.pyenv/versions/3.6.0/lib/python3.6/site-packages/tensorflow/python/framework/errors_impl.py", line 473, in __exit__
    c_api.TF_GetCode(self.status.status))
tensorflow.python.framework.errors_impl.InternalError: Blas GEMM launch failed : a.shape=(32, 50), b.shape=(50, 50), m=32, n=50, k=50
	 [[Node: dense_1/MatMul = MatMul[T=DT_FLOAT, transpose_a=false, transpose_b=false, _device="/job:localhost/replica:0/task:0/device:GPU:0"](_arg_dense_1_input_0_3/_117, dense_1/kernel/read)]]
	 [[Node: metrics/acc/Mean/_213 = _Recv[client_terminated=false, recv_device="/job:localhost/replica:0/task:0/device:CPU:0", send_device="/job:localhost/replica:0/task:0/device:GPU:0", send_device_incarnation=1, tensor_name="edge_1520_metrics/acc/Mean", tensor_type=DT_FLOAT, _device="/job:localhost/replica:0/task:0/device:CPU:0"]()]]

During handling of the above exception, another exception occurred:

Traceback (most recent call last):
  File "openpose_rw.py", line 63, in <module>
    fit = model.fit(X_train, y_train, verbose=2, epochs=800, validation_data=(X_test, y_test))
  File "/home/chikako_takasaki/.pyenv/versions/3.6.0/lib/python3.6/site-packages/keras/engine/training.py", line 1039, in fit
    validation_steps=validation_steps)
  File "/home/chikako_takasaki/.pyenv/versions/3.6.0/lib/python3.6/site-packages/keras/engine/training_arrays.py", line 199, in fit_loop
    outs = f(ins_batch)
  File "/home/chikako_takasaki/.pyenv/versions/3.6.0/lib/python3.6/site-packages/keras/backend/tensorflow_backend.py", line 2721, in __call__
    return self._legacy_call(inputs)
  File "/home/chikako_takasaki/.pyenv/versions/3.6.0/lib/python3.6/site-packages/keras/backend/tensorflow_backend.py", line 2693, in _legacy_call
    **self.session_kwargs)
  File "/home/chikako_takasaki/.pyenv/versions/3.6.0/lib/python3.6/site-packages/tensorflow/python/client/session.py", line 895, in run
    run_metadata_ptr)
  File "/home/chikako_takasaki/.pyenv/versions/3.6.0/lib/python3.6/site-packages/tensorflow/python/client/session.py", line 1128, in _run
    feed_dict_tensor, options, run_metadata)
  File "/home/chikako_takasaki/.pyenv/versions/3.6.0/lib/python3.6/site-packages/tensorflow/python/client/session.py", line 1344, in _do_run
    options, run_metadata)
  File "/home/chikako_takasaki/.pyenv/versions/3.6.0/lib/python3.6/site-packages/tensorflow/python/client/session.py", line 1363, in _do_call
    raise type(e)(node_def, op, message)
tensorflow.python.framework.errors_impl.InternalError: Blas GEMM launch failed : a.shape=(32, 50), b.shape=(50, 50), m=32, n=50, k=50
	 [[Node: dense_1/MatMul = MatMul[T=DT_FLOAT, transpose_a=false, transpose_b=false, _device="/job:localhost/replica:0/task:0/device:GPU:0"](_arg_dense_1_input_0_3/_117, dense_1/kernel/read)]]
	 [[Node: metrics/acc/Mean/_213 = _Recv[client_terminated=false, recv_device="/job:localhost/replica:0/task:0/device:CPU:0", send_device="/job:localhost/replica:0/task:0/device:GPU:0", send_device_incarnation=1, tensor_name="edge_1520_metrics/acc/Mean", tensor_type=DT_FLOAT, _device="/job:localhost/replica:0/task:0/device:CPU:0"]()]]

Caused by op 'dense_1/MatMul', defined at:
  File "openpose_rw.py", line 60, in <module>
    model = create_model()
  File "openpose_rw.py", line 50, in create_model
    Activation('sigmoid')
  File "/home/chikako_takasaki/.pyenv/versions/3.6.0/lib/python3.6/site-packages/keras/engine/sequential.py", line 93, in __init__
    self.add(layer)
  File "/home/chikako_takasaki/.pyenv/versions/3.6.0/lib/python3.6/site-packages/keras/engine/sequential.py", line 165, in add
    layer(x)
  File "/home/chikako_takasaki/.pyenv/versions/3.6.0/lib/python3.6/site-packages/keras/engine/base_layer.py", line 457, in __call__
    output = self.call(inputs, **kwargs)
  File "/home/chikako_takasaki/.pyenv/versions/3.6.0/lib/python3.6/site-packages/keras/layers/core.py", line 879, in call
    output = K.dot(inputs, self.kernel)
  File "/home/chikako_takasaki/.pyenv/versions/3.6.0/lib/python3.6/site-packages/keras/backend/tensorflow_backend.py", line 1085, in dot
    out = tf.matmul(x, y)
  File "/home/chikako_takasaki/.pyenv/versions/3.6.0/lib/python3.6/site-packages/tensorflow/python/ops/math_ops.py", line 2022, in matmul
    a, b, transpose_a=transpose_a, transpose_b=transpose_b, name=name)
  File "/home/chikako_takasaki/.pyenv/versions/3.6.0/lib/python3.6/site-packages/tensorflow/python/ops/gen_math_ops.py", line 2516, in _mat_mul
    name=name)
  File "/home/chikako_takasaki/.pyenv/versions/3.6.0/lib/python3.6/site-packages/tensorflow/python/framework/op_def_library.py", line 787, in _apply_op_helper
    op_def=op_def)
  File "/home/chikako_takasaki/.pyenv/versions/3.6.0/lib/python3.6/site-packages/tensorflow/python/framework/ops.py", line 3160, in create_op
    op_def=op_def)
  File "/home/chikako_takasaki/.pyenv/versions/3.6.0/lib/python3.6/site-packages/tensorflow/python/framework/ops.py", line 1625, in __init__
    self._traceback = self._graph._extract_stack()  # pylint: disable=protected-access

InternalError (see above for traceback): Blas GEMM launch failed : a.shape=(32, 50), b.shape=(50, 50), m=32, n=50, k=50
	 [[Node: dense_1/MatMul = MatMul[T=DT_FLOAT, transpose_a=false, transpose_b=false, _device="/job:localhost/replica:0/task:0/device:GPU:0"](_arg_dense_1_input_0_3/_117, dense_1/kernel/read)]]
	 [[Node: metrics/acc/Mean/_213 = _Recv[client_terminated=false, recv_device="/job:localhost/replica:0/task:0/device:CPU:0", send_device="/job:localhost/replica:0/task:0/device:GPU:0", send_device_incarnation=1, tensor_name="edge_1520_metrics/acc/Mean", tensor_type=DT_FLOAT, _device="/job:localhost/replica:0/task:0/device:CPU:0"]()]]

